Workbook

Sheet RESUMEN
A1: Última actualización: | B1: =TODAY() -> 46133
A2: Categoría | B2: Total | C2: Tengo | D2: Faltan | E2: Progreso | F2: Progreso VISUAL
A3: REGULARES | B3: 360 | C3: =COUNTIF(REGULARES!D:D, "SI") -> 341 | D3: =B3-C3 -> 19 | E3: =(C3/B3) -> 0.94722222 | F3: =IFERROR(__xludf.DUMMYFUNCTION("SPARKLINE(E3, {""charttype"",""bar""; ""max"",1; ""color1"",""green""; ""empty"",""ignore""})"),"")
A4: ESTADIOS | B4: 20 | C4: =COUNTIF(Estadios!D:D, "SI") -> 20 | D4: =B4-C4 -> 0 | E4: =(C4/B4) -> 1 | F4: =IFERROR(__xludf.DUMMYFUNCTION("SPARKLINE(E4, {""charttype"",""bar""; ""max"",1; ""color1"",""green""; ""empty"",""ignore""})"),"")
A5: VAMOS | B5: 20 | C5: =COUNTIF('¡VAMOS! (361–380)'!D:D, "SI") -> 19 | D5: =B5-C5 -> 1 | E5: =C5/B5 -> 0.95 | F5: =IFERROR(__xludf.DUMMYFUNCTION("SPARKLINE(E5, {""charttype"",""bar""; ""max"",1; ""color1"",""green""; ""empty"",""ignore""})"),"")
A6: Guantes de Oro | B6: 9 | C6: =COUNTIF('Guantes de Oro (381–387)'!D:D, "SI") -> 6 | D6: =B6-C6 -> 3 | E6: =C6/B6 -> 0.66666667 | F6: =IFERROR(__xludf.DUMMYFUNCTION("SPARKLINE(E6, {""charttype"",""bar""; ""max"",1; ""color1"",""green""; ""empty"",""ignore""})"),"")
A7: Kryptonita | B7: 12 | C7: =COUNTIF('Kryptonita (388–396)'!D:D, "SI") -> 7 | D7: =B7-C7 -> 5 | E7: =C7/B7 -> 0.58333333 | F7: =IFERROR(__xludf.DUMMYFUNCTION("SPARKLINE(E7, {""charttype"",""bar""; ""max"",1; ""color1"",""green""; ""empty"",""ignore""})"),"")
A8: Diamantes | B8: 18 | C8: =COUNTIF('Diamantes (397–414)'!D:D, "SI") -> 17 | D8: =B8-C8 -> 1 | E8: =C8/B8 -> 0.94444444 | F8: =IFERROR(__xludf.DUMMYFUNCTION("SPARKLINE(E8, {""charttype"",""bar""; ""max"",1; ""color1"",""green""; ""empty"",""ignore""})"),"")
A9: Influencers | B9: 13 | C9: =COUNTIF('Influencers (415–423)'!D:D, "SI") -> 12 | D9: =B9-C9 -> 1 | E9: =C9/B9 -> 0.92307692 | F9: =IFERROR(__xludf.DUMMYFUNCTION("SPARKLINE(E9, {""charttype"",""bar""; ""max"",1; ""color1"",""green""; ""empty"",""ignore""})"),"")
A10: Protas | B10: 18 | C10: =COUNTIF('Protas (424–441)'!D:D, "SI") -> 18 | D10: =B10-C10 -> 0 | E10: =C10/B10 -> 1 | F10: =IFERROR(__xludf.DUMMYFUNCTION("SPARKLINE(E10, {""charttype"",""bar""; ""max"",1; ""color1"",""green""; ""empty"",""ignore""})"),"")
A11: Super Cracks | B11: 26 | C11: =COUNTIF('Super Cracks (442–467)'!D:D, "SI") -> 24 | D11: =B11-C11 -> 2 | E11: =C11/B11 -> 0.92307692 | F11: =IFERROR(__xludf.DUMMYFUNCTION("SPARKLINE(E11, {""charttype"",""bar""; ""max"",1; ""color1"",""green""; ""empty"",""ignore""})"),"")
A12: CARTAS TOP | B12: 26 | C12: =COUNTIF('Cartas Top y Únicas (468–478)'!D:D, "SI") -> 18 | D12: =B12-C12 -> 8 | E12: =C12/B12 -> 0.69230769 | F12: =IFERROR(__xludf.DUMMYFUNCTION("SPARKLINE(E12, {""charttype"",""bar""; ""max"",1; ""color1"",""green""; ""empty"",""ignore""})"),"")
A13: Ampliación | B13: 102 | C13: =COUNTIF(AMPLIACION!D:D, "SI") -> 60 | D13: =B13-C13 -> 42 | E13: =C13/B13 -> 0.58823529 | F13: =IFERROR(__xludf.DUMMYFUNCTION("SPARKLINE(E13, {""charttype"",""bar""; ""max"",1; ""color1"",""green""; ""empty"",""ignore""})"),"")
A14: Especiales | B14: 84 | C14: =COUNTIF(ESPECIALES!D:D, "SI") -> 38 | D14: =B14-C14 -> 46 | E14: =C14/B14 -> 0.45238095 | F14: =IFERROR(__xludf.DUMMYFUNCTION("SPARKLINE(E14, {""charttype"",""bar""; ""max"",1; ""color1"",""green""; ""empty"",""ignore""})"),"")
A15: TOTAL COLECCIÓN | B15: =SUM(B3:B14) -> 708 | C15: =SUM(C3:C14) -> 580 | D15: =SUM(D3:D14) -> 128 | E15: =C15/B15 -> 0.81920904 | F15: =IFERROR(__xludf.DUMMYFUNCTION("SPARKLINE(E15, {""charttype"",""bar""; ""max"",1; ""color1"",""green""; ""empty"",""ignore""})"),"")

Sheet LO QUE ME FALTA
A1: =IFERROR(__xludf.DUMMYFUNCTION("FILTER( {REGULARES!A:C;'¡VAMOS! (361–380)'!A:C;'Guantes de Oro (381–387)'!A:C;'Kryptonita (388–396)'!A:C;'Diamantes (397–414)'!A:C;'Influencers (415–423)'!A:C;'Protas (424–441)'!A:C;'Super Cracks (442–467)'!A:C;'Cartas Top y Únicas (468–478)'!A:C;AMPLIA"&"CION!A:C;ESPECIALES!A:C;Estadios!A:C}, ({REGULARES!D:D;'¡VAMOS! (361–380)'!D:D;'Guantes de Oro (381–387)'!D:D;'Kryptonita (388–396)'!D:D;'Diamantes (397–414)'!D:D;'Influencers (415–423)'!D:D;'Protas (424–441)'!D:D;'Super Cracks (442–467)'!D:D;'Cartas To"&"p y Únicas (468–478)'!D:D;AMPLIACION!D:D;ESPECIALES!D:D;Estadios!D:D}<>""SI"")* ({REGULARES!A:A;'¡VAMOS! (361–380)'!A:A;'Guantes de Oro (381–387)'!A:A;'Kryptonita (388–396)'!A:A;'Diamantes (397–414)'!A:A;'Influencers (415–423)'!A:A;'Protas (424–441)'!A:"&"A;'Super Cracks (442–467)'!A:A;'Cartas Top y Únicas (468–478)'!A:A;AMPLIACION!A:A;ESPECIALES!A:A;Estadios!A:A}<>"""") )"),13.0) -> 13 | B1: =IFERROR(__xludf.DUMMYFUNCTION("""COMPUTED_VALUE"""),"PABLO IBÁÑEZ") -> PABLO IBÁÑEZ | C1: =IFERROR(__xludf.DUMMYFUNCTION("""COMPUTED_VALUE"""),"D. ALAVÉS") -> D. ALAVÉS
A2: =IFERROR(__xludf.DUMMYFUNCTION("""COMPUTED_VALUE"""),20.0) -> 20 | B2: =IFERROR(__xludf.DUMMYFUNCTION("""COMPUTED_VALUE"""),"UNAI SIMÓN") -> UNAI SIMÓN | C2: =IFERROR(__xludf.DUMMYFUNCTION("""COMPUTED_VALUE"""),"ATHLETIC CLUB") -> ATHLETIC CLUB
A3: =IFERROR(__xludf.DUMMYFUNCTION("""COMPUTED_VALUE"""),26.0) -> 26 | B3: =IFERROR(__xludf.DUMMYFUNCTION("""COMPUTED_VALUE"""),"YURI") -> YURI | C3: =IFERROR(__xludf.DUMMYFUNCTION("""COMPUTED_VALUE"""),"ATHLETIC CLUB") -> ATHLETIC CLUB
A4: =IFERROR(__xludf.DUMMYFUNCTION("""COMPUTED_VALUE"""),57.0) -> 57 | B4: =IFERROR(__xludf.DUMMYFUNCTION("""COMPUTED_VALUE"""),"SZCZESNY") -> SZCZESNY | C4: =IFERROR(__xludf.DUMMYFUNCTION("""COMPUTED_VALUE"""),"FC BARCELONA") -> FC BARCELONA
A5: =IFERROR(__xludf.DUMMYFUNCTION("""COMPUTED_VALUE"""),83.0) -> 83 | B5: =IFERROR(__xludf.DUMMYFUNCTION("""COMPUTED_VALUE"""),"AMRABAT") -> AMRABAT | C5: =IFERROR(__xludf.DUMMYFUNCTION("""COMPUTED_VALUE"""),"REAL BETIS") -> REAL BETIS
A6: =IFERROR(__xludf.DUMMYFUNCTION("""COMPUTED_VALUE"""),85.0) -> 85 | B6: =IFERROR(__xludf.DUMMYFUNCTION("""COMPUTED_VALUE"""),"LO CELSO") -> LO CELSO | C6: =IFERROR(__xludf.DUMMYFUNCTION("""COMPUTED_VALUE"""),"REAL BETIS") -> REAL BETIS
A7: =IFERROR(__xludf.DUMMYFUNCTION("""COMPUTED_VALUE"""),89.0) -> 89 | B7: =IFERROR(__xludf.DUMMYFUNCTION("""COMPUTED_VALUE"""),"RIQUELME") -> RIQUELME | C7: =IFERROR(__xludf.DUMMYFUNCTION("""COMPUTED_VALUE"""),"REAL BETIS") -> REAL BETIS
A8: =IFERROR(__xludf.DUMMYFUNCTION("""COMPUTED_VALUE"""),90.0) -> 90 | B8: =IFERROR(__xludf.DUMMYFUNCTION("""COMPUTED_VALUE"""),"ABDE") -> ABDE | C8: =IFERROR(__xludf.DUMMYFUNCTION("""COMPUTED_VALUE"""),"REAL BETIS") -> REAL BETIS
A9: =IFERROR(__xludf.DUMMYFUNCTION("""COMPUTED_VALUE"""),92.0) -> 92 | B9: =IFERROR(__xludf.DUMMYFUNCTION("""COMPUTED_VALUE"""),"RADU") -> RADU | C9: =IFERROR(__xludf.DUMMYFUNCTION("""COMPUTED_VALUE"""),"RC CELTA") -> RC CELTA
A10: =IFERROR(__xludf.DUMMYFUNCTION("""COMPUTED_VALUE"""),119.0) -> 119 | B10: =IFERROR(__xludf.DUMMYFUNCTION("""COMPUTED_VALUE"""),"MARTIM NETO") -> MARTIM NETO | C10: =IFERROR(__xludf.DUMMYFUNCTION("""COMPUTED_VALUE"""),"ELCHE CF") -> ELCHE CF
A11: =IFERROR(__xludf.DUMMYFUNCTION("""COMPUTED_VALUE"""),133.0) -> 133 | B11: =IFERROR(__xludf.DUMMYFUNCTION("""COMPUTED_VALUE"""),"CABRERA") -> CABRERA | C11: =IFERROR(__xludf.DUMMYFUNCTION("""COMPUTED_VALUE"""),"RCD ESPANYOL") -> RCD ESPANYOL
A12: =IFERROR(__xludf.DUMMYFUNCTION("""COMPUTED_VALUE"""),196.0) -> 196 | B12: =IFERROR(__xludf.DUMMYFUNCTION("""COMPUTED_VALUE"""),"BRUGUÉ") -> BRUGUÉ | C12: =IFERROR(__xludf.DUMMYFUNCTION("""COMPUTED_VALUE"""),"LEVANTE UD") -> LEVANTE UD
A13: =IFERROR(__xludf.DUMMYFUNCTION("""COMPUTED_VALUE"""),232.0) -> 232 | B13: =IFERROR(__xludf.DUMMYFUNCTION("""COMPUTED_VALUE"""),"MURIQI") -> MURIQI | C13: =IFERROR(__xludf.DUMMYFUNCTION("""COMPUTED_VALUE"""),"RCD MALLORCA") -> RCD MALLORCA
A14: =IFERROR(__xludf.DUMMYFUNCTION("""COMPUTED_VALUE"""),233.0) -> 233 | B14: =IFERROR(__xludf.DUMMYFUNCTION("""COMPUTED_VALUE"""),"MATEO JOSEPH") -> MATEO JOSEPH | C14: =IFERROR(__xludf.DUMMYFUNCTION("""COMPUTED_VALUE"""),"RCD MALLORCA") -> RCD MALLORCA
A15: =IFERROR(__xludf.DUMMYFUNCTION("""COMPUTED_VALUE"""),241.0) -> 241 | B15: =IFERROR(__xludf.DUMMYFUNCTION("""COMPUTED_VALUE"""),"HERRANDO") -> HERRANDO | C15: =IFERROR(__xludf.DUMMYFUNCTION("""COMPUTED_VALUE"""),"CA OSASUNA") -> CA OSASUNA
A16: =IFERROR(__xludf.DUMMYFUNCTION("""COMPUTED_VALUE"""),253.0) -> 253 | B16: =IFERROR(__xludf.DUMMYFUNCTION("""COMPUTED_VALUE"""),"ESCUDO") -> ESCUDO | C16: =IFERROR(__xludf.DUMMYFUNCTION("""COMPUTED_VALUE"""),"REAL OVIEDO") -> REAL OVIEDO
A17: =IFERROR(__xludf.DUMMYFUNCTION("""COMPUTED_VALUE"""),263.0) -> 263 | B17: =IFERROR(__xludf.DUMMYFUNCTION("""COMPUTED_VALUE"""),"DENDONCKER") -> DENDONCKER | C17: =IFERROR(__xludf.DUMMYFUNCTION("""COMPUTED_VALUE"""),"REAL OVIEDO") -> REAL OVIEDO
A18: =IFERROR(__xludf.DUMMYFUNCTION("""COMPUTED_VALUE"""),276.0) -> 276 | B18: =IFERROR(__xludf.DUMMYFUNCTION("""COMPUTED_VALUE"""),"LEJEUNE") -> LEJEUNE | C18: =IFERROR(__xludf.DUMMYFUNCTION("""COMPUTED_VALUE"""),"RAYO VALLECANO") -> RAYO VALLECANO
A19: =IFERROR(__xludf.DUMMYFUNCTION("""COMPUTED_VALUE"""),310.0) -> 310 | B19: =IFERROR(__xludf.DUMMYFUNCTION("""COMPUTED_VALUE"""),"CARMONA") -> CARMONA | C19: =IFERROR(__xludf.DUMMYFUNCTION("""COMPUTED_VALUE"""),"SEVILLA FC") -> SEVILLA FC
A20: =IFERROR(__xludf.DUMMYFUNCTION("""COMPUTED_VALUE"""),380.0) -> 380 | B20: =IFERROR(__xludf.DUMMYFUNCTION("""COMPUTED_VALUE"""),"VILLARREAL CF") -> VILLARREAL CF | C20: =IFERROR(__xludf.DUMMYFUNCTION("""COMPUTED_VALUE"""),"¡VAMOS!") -> ¡VAMOS!
A21: =IFERROR(__xludf.DUMMYFUNCTION("""COMPUTED_VALUE"""),385.0) -> 385 | B21: =IFERROR(__xludf.DUMMYFUNCTION("""COMPUTED_VALUE"""),"BATALLA") -> BATALLA | C21: =IFERROR(__xludf.DUMMYFUNCTION("""COMPUTED_VALUE"""),"RAYO VALLECANO") -> RAYO VALLECANO
A22: =IFERROR(__xludf.DUMMYFUNCTION("""COMPUTED_VALUE"""),499.0) -> 499 | B22: =IFERROR(__xludf.DUMMYFUNCTION("""COMPUTED_VALUE"""),"DMITROVIC") -> DMITROVIC | C22: =IFERROR(__xludf.DUMMYFUNCTION("""COMPUTED_VALUE"""),"RCD ESPANYOL") -> RCD ESPANYOL
A23: =IFERROR(__xludf.DUMMYFUNCTION("""COMPUTED_VALUE"""),500.0) -> 500 | B23: =IFERROR(__xludf.DUMMYFUNCTION("""COMPUTED_VALUE"""),"TER STEGEN") -> TER STEGEN | C23: =IFERROR(__xludf.DUMMYFUNCTION("""COMPUTED_VALUE"""),"GIRONA FC") -> GIRONA FC
A24: =IFERROR(__xludf.DUMMYFUNCTION("""COMPUTED_VALUE"""),390.0) -> 390 | B24: =IFERROR(__xludf.DUMMYFUNCTION("""COMPUTED_VALUE"""),"LE NORMAND") -> LE NORMAND | C24: =IFERROR(__xludf.DUMMYFUNCTION("""COMPUTED_VALUE"""),"ATLÉTICO DE MADRID") -> ATLÉTICO DE MADRID
A25: =IFERROR(__xludf.DUMMYFUNCTION("""COMPUTED_VALUE"""),394.0) -> 394 | B25: =IFERROR(__xludf.DUMMYFUNCTION("""COMPUTED_VALUE"""),"LEJEUNE") -> LEJEUNE | C25: =IFERROR(__xludf.DUMMYFUNCTION("""COMPUTED_VALUE"""),"RAYO VALLECANO") -> RAYO VALLECANO
A26: =IFERROR(__xludf.DUMMYFUNCTION("""COMPUTED_VALUE"""),501.0) -> 501 | B26: =IFERROR(__xludf.DUMMYFUNCTION("""COMPUTED_VALUE"""),"PUBILL") -> PUBILL | C26: =IFERROR(__xludf.DUMMYFUNCTION("""COMPUTED_VALUE"""),"ATLÉTICO DE MADRID") -> ATLÉTICO DE MADRID
A27: =IFERROR(__xludf.DUMMYFUNCTION("""COMPUTED_VALUE"""),502.0) -> 502 | B27: =IFERROR(__xludf.DUMMYFUNCTION("""COMPUTED_VALUE"""),"GERARD MARTÍN") -> GERARD MARTÍN | C27: =IFERROR(__xludf.DUMMYFUNCTION("""COMPUTED_VALUE"""),"FC BARCELONA") -> FC BARCELONA
A28: =IFERROR(__xludf.DUMMYFUNCTION("""COMPUTED_VALUE"""),503.0) -> 503 | B28: =IFERROR(__xludf.DUMMYFUNCTION("""COMPUTED_VALUE"""),"ASENCIO") -> ASENCIO | C28: =IFERROR(__xludf.DUMMYFUNCTION("""COMPUTED_VALUE"""),"REAL MADRID") -> REAL MADRID
A29: =IFERROR(__xludf.DUMMYFUNCTION("""COMPUTED_VALUE"""),412.0) -> 412 | B29: =IFERROR(__xludf.DUMMYFUNCTION("""COMPUTED_VALUE"""),"MATEO JOSEPH") -> MATEO JOSEPH | C29: =IFERROR(__xludf.DUMMYFUNCTION("""COMPUTED_VALUE"""),"RCD MALLORCA") -> RCD MALLORCA
A30: =IFERROR(__xludf.DUMMYFUNCTION("""COMPUTED_VALUE"""),"416 Bis") -> 416 Bis | B30: =IFERROR(__xludf.DUMMYFUNCTION("""COMPUTED_VALUE"""),"PABLO FORNALS") -> PABLO FORNALS | C30: =IFERROR(__xludf.DUMMYFUNCTION("""COMPUTED_VALUE"""),"REAL BETIS") -> REAL BETIS
A31: =IFERROR(__xludf.DUMMYFUNCTION("""COMPUTED_VALUE"""),443.0) -> 443 | B31: =IFERROR(__xludf.DUMMYFUNCTION("""COMPUTED_VALUE"""),"JAUREGIZAR") -> JAUREGIZAR | C31: =IFERROR(__xludf.DUMMYFUNCTION("""COMPUTED_VALUE"""),"ATHLETIC CLUB") -> ATHLETIC CLUB
A32: =IFERROR(__xludf.DUMMYFUNCTION("""COMPUTED_VALUE"""),453.0) -> 453 | B32: =IFERROR(__xludf.DUMMYFUNCTION("""COMPUTED_VALUE"""),"RASHFORD") -> RASHFORD | C32: =IFERROR(__xludf.DUMMYFUNCTION("""COMPUTED_VALUE"""),"FC BARCELONA") -> FC BARCELONA
A33: =IFERROR(__xludf.DUMMYFUNCTION("""COMPUTED_VALUE"""),470.0) -> 470 | B33: =IFERROR(__xludf.DUMMYFUNCTION("""COMPUTED_VALUE"""),"JULIÁN ÁLVAREZ") -> JULIÁN ÁLVAREZ | C33: =IFERROR(__xludf.DUMMYFUNCTION("""COMPUTED_VALUE"""),"BALÓN DE ORO (ATLÉTICO)") -> BALÓN DE ORO (ATLÉTICO)
A34: =IFERROR(__xludf.DUMMYFUNCTION("""COMPUTED_VALUE"""),471.0) -> 471 | B34: =IFERROR(__xludf.DUMMYFUNCTION("""COMPUTED_VALUE"""),"PEDRI") -> PEDRI | C34: =IFERROR(__xludf.DUMMYFUNCTION("""COMPUTED_VALUE"""),"BALÓN DE ORO (BARÇA)") -> BALÓN DE ORO (BARÇA)
A35: =IFERROR(__xludf.DUMMYFUNCTION("""COMPUTED_VALUE"""),472.0) -> 472 | B35: =IFERROR(__xludf.DUMMYFUNCTION("""COMPUTED_VALUE"""),"LAMINE YAMAL") -> LAMINE YAMAL | C35: =IFERROR(__xludf.DUMMYFUNCTION("""COMPUTED_VALUE"""),"BALÓN DE ORO (BARÇA)") -> BALÓN DE ORO (BARÇA)
A36: =IFERROR(__xludf.DUMMYFUNCTION("""COMPUTED_VALUE"""),476.0) -> 476 | B36: =IFERROR(__xludf.DUMMYFUNCTION("""COMPUTED_VALUE"""),"CARD ATÓMICA") -> CARD ATÓMICA | C36: =IFERROR(__xludf.DUMMYFUNCTION("""COMPUTED_VALUE"""),"ÚNICA") -> ÚNICA
A37: =IFERROR(__xludf.DUMMYFUNCTION("""COMPUTED_VALUE"""),"2MN") -> 2MN | B37: =IFERROR(__xludf.DUMMYFUNCTION("""COMPUTED_VALUE"""),"RADU") -> RADU | C37: =IFERROR(__xludf.DUMMYFUNCTION("""COMPUTED_VALUE"""),"CELTA") -> CELTA
A38: =IFERROR(__xludf.DUMMYFUNCTION("""COMPUTED_VALUE"""),"6MN") -> 6MN | B38: =IFERROR(__xludf.DUMMYFUNCTION("""COMPUTED_VALUE"""),"SUAZO") -> SUAZO | C38: =IFERROR(__xludf.DUMMYFUNCTION("""COMPUTED_VALUE"""),"SEVILLA FC") -> SEVILLA FC
A39: =IFERROR(__xludf.DUMMYFUNCTION("""COMPUTED_VALUE"""),"12MN") -> 12MN | B39: =IFERROR(__xludf.DUMMYFUNCTION("""COMPUTED_VALUE"""),"DOLAN") -> DOLAN | C39: =IFERROR(__xludf.DUMMYFUNCTION("""COMPUTED_VALUE"""),"RCD ESPANYOL") -> RCD ESPANYOL
A40: =IFERROR(__xludf.DUMMYFUNCTION("""COMPUTED_VALUE"""),"13MN") -> 13MN | B40: =IFERROR(__xludf.DUMMYFUNCTION("""COMPUTED_VALUE"""),"MIKAUTADZE") -> MIKAUTADZE | C40: =IFERROR(__xludf.DUMMYFUNCTION("""COMPUTED_VALUE"""),"VILLAREAL CF") -> VILLAREAL CF
...

Sheet REPETIDOS
A1: =IFERROR(__xludf.DUMMYFUNCTION("FILTER( {REGULARES!A:C,REGULARES!E:E;'¡VAMOS! (361–380)'!A:C,'¡VAMOS! (361–380)'!E:E;'Guantes de Oro (381–387)'!A:C,'Guantes de Oro (381–387)'!E:E;'Kryptonita (388–396)'!A:C,'Kryptonita (388–396)'!E:E;'Diamantes (397–414)'!A:C,'Diamantes (397–414)'!E:E;"&"'Influencers (415–423)'!A:C,'Influencers (415–423)'!E:E;'Protas (424–441)'!A:C,'Protas (424–441)'!E:E;'Super Cracks (442–467)'!A:C,'Super Cracks (442–467)'!E:E;'Cartas Top y Únicas (468–478)'!A:C,'Cartas Top y Únicas (468–478)'!E:E;AMPLIACION!A:C,AMPLIACI"&"ON!E:E;ESPECIALES!A:C,ESPECIALES!E:E;Estadios!A:C,Estadios!E:E}, {REGULARES!E:E;'¡VAMOS! (361–380)'!E:E;'Guantes de Oro (381–387)'!E:E;'Kryptonita (388–396)'!E:E;'Diamantes (397–414)'!E:E;'Influencers (415–423)'!E:E;'Protas (424–441)'!E:E;'Super Cracks "&"(442–467)'!E:E;'Cartas Top y Únicas (468–478)'!E:E;AMPLIACION!E:E;ESPECIALES!E:E;Estadios!E:E}>0 )"),1.0) -> 1 | B1: =IFERROR(__xludf.DUMMYFUNCTION("""COMPUTED_VALUE"""),"ESCUDO") -> ESCUDO | C1: =IFERROR(__xludf.DUMMYFUNCTION("""COMPUTED_VALUE"""),"D. ALAVÉS") -> D. ALAVÉS | D1: =IFERROR(__xludf.DUMMYFUNCTION("""COMPUTED_VALUE"""),1.0) -> 1
A2: =IFERROR(__xludf.DUMMYFUNCTION("""COMPUTED_VALUE"""),3.0) -> 3 | B2: =IFERROR(__xludf.DUMMYFUNCTION("""COMPUTED_VALUE"""),"RAÚL FERNÁNDEZ") -> RAÚL FERNÁNDEZ | C2: =IFERROR(__xludf.DUMMYFUNCTION("""COMPUTED_VALUE"""),"D. ALAVÉS") -> D. ALAVÉS | D2: =IFERROR(__xludf.DUMMYFUNCTION("""COMPUTED_VALUE"""),1.0) -> 1
A3: =IFERROR(__xludf.DUMMYFUNCTION("""COMPUTED_VALUE"""),4.0) -> 4 | B3: =IFERROR(__xludf.DUMMYFUNCTION("""COMPUTED_VALUE"""),"JONNY") -> JONNY | C3: =IFERROR(__xludf.DUMMYFUNCTION("""COMPUTED_VALUE"""),"D. ALAVÉS") -> D. ALAVÉS | D3: =IFERROR(__xludf.DUMMYFUNCTION("""COMPUTED_VALUE"""),1.0) -> 1
A4: =IFERROR(__xludf.DUMMYFUNCTION("""COMPUTED_VALUE"""),5.0) -> 5 | B4: =IFERROR(__xludf.DUMMYFUNCTION("""COMPUTED_VALUE"""),"TENAGLIA") -> TENAGLIA | C4: =IFERROR(__xludf.DUMMYFUNCTION("""COMPUTED_VALUE"""),"D. ALAVÉS") -> D. ALAVÉS | D4: =IFERROR(__xludf.DUMMYFUNCTION("""COMPUTED_VALUE"""),1.0) -> 1
A5: =IFERROR(__xludf.DUMMYFUNCTION("""COMPUTED_VALUE"""),7.0) -> 7 | B5: =IFERROR(__xludf.DUMMYFUNCTION("""COMPUTED_VALUE"""),"PARADA") -> PARADA | C5: =IFERROR(__xludf.DUMMYFUNCTION("""COMPUTED_VALUE"""),"D. ALAVÉS") -> D. ALAVÉS | D5: =IFERROR(__xludf.DUMMYFUNCTION("""COMPUTED_VALUE"""),1.0) -> 1
A6: =IFERROR(__xludf.DUMMYFUNCTION("""COMPUTED_VALUE"""),8.0) -> 8 | B6: =IFERROR(__xludf.DUMMYFUNCTION("""COMPUTED_VALUE"""),"MOUSSA DIARRA") -> MOUSSA DIARRA | C6: =IFERROR(__xludf.DUMMYFUNCTION("""COMPUTED_VALUE"""),"D. ALAVÉS") -> D. ALAVÉS | D6: =IFERROR(__xludf.DUMMYFUNCTION("""COMPUTED_VALUE"""),1.0) -> 1
A7: =IFERROR(__xludf.DUMMYFUNCTION("""COMPUTED_VALUE"""),15.0) -> 15 | B7: =IFERROR(__xludf.DUMMYFUNCTION("""COMPUTED_VALUE"""),"CARLOS VICENTE") -> CARLOS VICENTE | C7: =IFERROR(__xludf.DUMMYFUNCTION("""COMPUTED_VALUE"""),"D. ALAVÉS") -> D. ALAVÉS | D7: =IFERROR(__xludf.DUMMYFUNCTION("""COMPUTED_VALUE"""),1.0) -> 1
A8: =IFERROR(__xludf.DUMMYFUNCTION("""COMPUTED_VALUE"""),16.0) -> 16 | B8: =IFERROR(__xludf.DUMMYFUNCTION("""COMPUTED_VALUE"""),"TONI MARTÍNEZ") -> TONI MARTÍNEZ | C8: =IFERROR(__xludf.DUMMYFUNCTION("""COMPUTED_VALUE"""),"D. ALAVÉS") -> D. ALAVÉS | D8: =IFERROR(__xludf.DUMMYFUNCTION("""COMPUTED_VALUE"""),1.0) -> 1
A9: =IFERROR(__xludf.DUMMYFUNCTION("""COMPUTED_VALUE"""),17.0) -> 17 | B9: =IFERROR(__xludf.DUMMYFUNCTION("""COMPUTED_VALUE"""),"BOYÉ") -> BOYÉ | C9: =IFERROR(__xludf.DUMMYFUNCTION("""COMPUTED_VALUE"""),"D. ALAVÉS") -> D. ALAVÉS | D9: =IFERROR(__xludf.DUMMYFUNCTION("""COMPUTED_VALUE"""),1.0) -> 1
A10: =IFERROR(__xludf.DUMMYFUNCTION("""COMPUTED_VALUE"""),18.0) -> 18 | B10: =IFERROR(__xludf.DUMMYFUNCTION("""COMPUTED_VALUE"""),"MARIANO") -> MARIANO | C10: =IFERROR(__xludf.DUMMYFUNCTION("""COMPUTED_VALUE"""),"D. ALAVÉS") -> D. ALAVÉS | D10: =IFERROR(__xludf.DUMMYFUNCTION("""COMPUTED_VALUE"""),2.0) -> 2
A11: =IFERROR(__xludf.DUMMYFUNCTION("""COMPUTED_VALUE"""),19.0) -> 19 | B11: =IFERROR(__xludf.DUMMYFUNCTION("""COMPUTED_VALUE"""),"ESCUDO") -> ESCUDO | C11: =IFERROR(__xludf.DUMMYFUNCTION("""COMPUTED_VALUE"""),"ATHLETIC CLUB") -> ATHLETIC CLUB | D11: =IFERROR(__xludf.DUMMYFUNCTION("""COMPUTED_VALUE"""),1.0) -> 1
A12: =IFERROR(__xludf.DUMMYFUNCTION("""COMPUTED_VALUE"""),21.0) -> 21 | B12: =IFERROR(__xludf.DUMMYFUNCTION("""COMPUTED_VALUE"""),"PADILLA") -> PADILLA | C12: =IFERROR(__xludf.DUMMYFUNCTION("""COMPUTED_VALUE"""),"ATHLETIC CLUB") -> ATHLETIC CLUB | D12: =IFERROR(__xludf.DUMMYFUNCTION("""COMPUTED_VALUE"""),1.0) -> 1
A13: =IFERROR(__xludf.DUMMYFUNCTION("""COMPUTED_VALUE"""),23.0) -> 23 | B13: =IFERROR(__xludf.DUMMYFUNCTION("""COMPUTED_VALUE"""),"VIVIAN") -> VIVIAN | C13: =IFERROR(__xludf.DUMMYFUNCTION("""COMPUTED_VALUE"""),"ATHLETIC CLUB") -> ATHLETIC CLUB | D13: =IFERROR(__xludf.DUMMYFUNCTION("""COMPUTED_VALUE"""),2.0) -> 2
A14: =IFERROR(__xludf.DUMMYFUNCTION("""COMPUTED_VALUE"""),27.0) -> 27 | B14: =IFERROR(__xludf.DUMMYFUNCTION("""COMPUTED_VALUE"""),"RUIZ DE GALARRETA") -> RUIZ DE GALARRETA | C14: =IFERROR(__xludf.DUMMYFUNCTION("""COMPUTED_VALUE"""),"ATHLETIC CLUB") -> ATHLETIC CLUB | D14: =IFERROR(__xludf.DUMMYFUNCTION("""COMPUTED_VALUE"""),1.0) -> 1
A15: =IFERROR(__xludf.DUMMYFUNCTION("""COMPUTED_VALUE"""),31.0) -> 31 | B15: =IFERROR(__xludf.DUMMYFUNCTION("""COMPUTED_VALUE"""),"SANCET") -> SANCET | C15: =IFERROR(__xludf.DUMMYFUNCTION("""COMPUTED_VALUE"""),"ATHLETIC CLUB") -> ATHLETIC CLUB | D15: =IFERROR(__xludf.DUMMYFUNCTION("""COMPUTED_VALUE"""),1.0) -> 1
A16: =IFERROR(__xludf.DUMMYFUNCTION("""COMPUTED_VALUE"""),32.0) -> 32 | B16: =IFERROR(__xludf.DUMMYFUNCTION("""COMPUTED_VALUE"""),"BERENGUER") -> BERENGUER | C16: =IFERROR(__xludf.DUMMYFUNCTION("""COMPUTED_VALUE"""),"ATHLETIC CLUB") -> ATHLETIC CLUB | D16: =IFERROR(__xludf.DUMMYFUNCTION("""COMPUTED_VALUE"""),1.0) -> 1
A17: =IFERROR(__xludf.DUMMYFUNCTION("""COMPUTED_VALUE"""),33.0) -> 33 | B17: =IFERROR(__xludf.DUMMYFUNCTION("""COMPUTED_VALUE"""),"WILLIAMS") -> WILLIAMS | C17: =IFERROR(__xludf.DUMMYFUNCTION("""COMPUTED_VALUE"""),"ATHLETIC CLUB") -> ATHLETIC CLUB | D17: =IFERROR(__xludf.DUMMYFUNCTION("""COMPUTED_VALUE"""),1.0) -> 1
A18: =IFERROR(__xludf.DUMMYFUNCTION("""COMPUTED_VALUE"""),34.0) -> 34 | B18: =IFERROR(__xludf.DUMMYFUNCTION("""COMPUTED_VALUE"""),"MAROAN") -> MAROAN | C18: =IFERROR(__xludf.DUMMYFUNCTION("""COMPUTED_VALUE"""),"ATHLETIC CLUB") -> ATHLETIC CLUB | D18: =IFERROR(__xludf.DUMMYFUNCTION("""COMPUTED_VALUE"""),1.0) -> 1
A19: =IFERROR(__xludf.DUMMYFUNCTION("""COMPUTED_VALUE"""),39.0) -> 39 | B19: =IFERROR(__xludf.DUMMYFUNCTION("""COMPUTED_VALUE"""),"MUSSO") -> MUSSO | C19: =IFERROR(__xludf.DUMMYFUNCTION("""COMPUTED_VALUE"""),"ATLÉTICO DE MADRID") -> ATLÉTICO DE MADRID | D19: =IFERROR(__xludf.DUMMYFUNCTION("""COMPUTED_VALUE"""),2.0) -> 2
A20: =IFERROR(__xludf.DUMMYFUNCTION("""COMPUTED_VALUE"""),40.0) -> 40 | B20: =IFERROR(__xludf.DUMMYFUNCTION("""COMPUTED_VALUE"""),"MARCOS LLORENTE") -> MARCOS LLORENTE | C20: =IFERROR(__xludf.DUMMYFUNCTION("""COMPUTED_VALUE"""),"ATLÉTICO DE MADRID") -> ATLÉTICO DE MADRID | D20: =IFERROR(__xludf.DUMMYFUNCTION("""COMPUTED_VALUE"""),1.0) -> 1
A21: =IFERROR(__xludf.DUMMYFUNCTION("""COMPUTED_VALUE"""),42.0) -> 42 | B21: =IFERROR(__xludf.DUMMYFUNCTION("""COMPUTED_VALUE"""),"LENGLET") -> LENGLET | C21: =IFERROR(__xludf.DUMMYFUNCTION("""COMPUTED_VALUE"""),"ATLÉTICO DE MADRID") -> ATLÉTICO DE MADRID | D21: =IFERROR(__xludf.DUMMYFUNCTION("""COMPUTED_VALUE"""),3.0) -> 3
A22: =IFERROR(__xludf.DUMMYFUNCTION("""COMPUTED_VALUE"""),43.0) -> 43 | B22: =IFERROR(__xludf.DUMMYFUNCTION("""COMPUTED_VALUE"""),"HANCKO") -> HANCKO | C22: =IFERROR(__xludf.DUMMYFUNCTION("""COMPUTED_VALUE"""),"ATLÉTICO DE MADRID") -> ATLÉTICO DE MADRID | D22: =IFERROR(__xludf.DUMMYFUNCTION("""COMPUTED_VALUE"""),1.0) -> 1
A23: =IFERROR(__xludf.DUMMYFUNCTION("""COMPUTED_VALUE"""),46.0) -> 46 | B23: =IFERROR(__xludf.DUMMYFUNCTION("""COMPUTED_VALUE"""),"BARRIOS") -> BARRIOS | C23: =IFERROR(__xludf.DUMMYFUNCTION("""COMPUTED_VALUE"""),"ATLÉTICO DE MADRID") -> ATLÉTICO DE MADRID | D23: =IFERROR(__xludf.DUMMYFUNCTION("""COMPUTED_VALUE"""),1.0) -> 1
A24: =IFERROR(__xludf.DUMMYFUNCTION("""COMPUTED_VALUE"""),48.0) -> 48 | B24: =IFERROR(__xludf.DUMMYFUNCTION("""COMPUTED_VALUE"""),"ALEX BAENA") -> ALEX BAENA | C24: =IFERROR(__xludf.DUMMYFUNCTION("""COMPUTED_VALUE"""),"ATLÉTICO DE MADRID") -> ATLÉTICO DE MADRID | D24: =IFERROR(__xludf.DUMMYFUNCTION("""COMPUTED_VALUE"""),1.0) -> 1
A25: =IFERROR(__xludf.DUMMYFUNCTION("""COMPUTED_VALUE"""),49.0) -> 49 | B25: =IFERROR(__xludf.DUMMYFUNCTION("""COMPUTED_VALUE"""),"ALMADA") -> ALMADA | C25: =IFERROR(__xludf.DUMMYFUNCTION("""COMPUTED_VALUE"""),"ATLÉTICO DE MADRID") -> ATLÉTICO DE MADRID | D25: =IFERROR(__xludf.DUMMYFUNCTION("""COMPUTED_VALUE"""),2.0) -> 2
A26: =IFERROR(__xludf.DUMMYFUNCTION("""COMPUTED_VALUE"""),52.0) -> 52 | B26: =IFERROR(__xludf.DUMMYFUNCTION("""COMPUTED_VALUE"""),"JULIÁN ALVAREZ") -> JULIÁN ALVAREZ | C26: =IFERROR(__xludf.DUMMYFUNCTION("""COMPUTED_VALUE"""),"ATLÉTICO DE MADRID") -> ATLÉTICO DE MADRID | D26: =IFERROR(__xludf.DUMMYFUNCTION("""COMPUTED_VALUE"""),1.0) -> 1
A27: =IFERROR(__xludf.DUMMYFUNCTION("""COMPUTED_VALUE"""),55.0) -> 55 | B27: =IFERROR(__xludf.DUMMYFUNCTION("""COMPUTED_VALUE"""),"ESCUDO") -> ESCUDO | C27: =IFERROR(__xludf.DUMMYFUNCTION("""COMPUTED_VALUE"""),"FC BARCELONA") -> FC BARCELONA | D27: =IFERROR(__xludf.DUMMYFUNCTION("""COMPUTED_VALUE"""),1.0) -> 1
A28: =IFERROR(__xludf.DUMMYFUNCTION("""COMPUTED_VALUE"""),60.0) -> 60 | B28: =IFERROR(__xludf.DUMMYFUNCTION("""COMPUTED_VALUE"""),"ERIC GARCÍA") -> ERIC GARCÍA | C28: =IFERROR(__xludf.DUMMYFUNCTION("""COMPUTED_VALUE"""),"FC BARCELONA") -> FC BARCELONA | D28: =IFERROR(__xludf.DUMMYFUNCTION("""COMPUTED_VALUE"""),1.0) -> 1
A29: =IFERROR(__xludf.DUMMYFUNCTION("""COMPUTED_VALUE"""),61.0) -> 61 | B29: =IFERROR(__xludf.DUMMYFUNCTION("""COMPUTED_VALUE"""),"ARAÚJO") -> ARAÚJO | C29: =IFERROR(__xludf.DUMMYFUNCTION("""COMPUTED_VALUE"""),"FC BARCELONA") -> FC BARCELONA | D29: =IFERROR(__xludf.DUMMYFUNCTION("""COMPUTED_VALUE"""),1.0) -> 1
A30: =IFERROR(__xludf.DUMMYFUNCTION("""COMPUTED_VALUE"""),62.0) -> 62 | B30: =IFERROR(__xludf.DUMMYFUNCTION("""COMPUTED_VALUE"""),"BALDE") -> BALDE | C30: =IFERROR(__xludf.DUMMYFUNCTION("""COMPUTED_VALUE"""),"FC BARCELONA") -> FC BARCELONA | D30: =IFERROR(__xludf.DUMMYFUNCTION("""COMPUTED_VALUE"""),1.0) -> 1
A31: =IFERROR(__xludf.DUMMYFUNCTION("""COMPUTED_VALUE"""),63.0) -> 63 | B31: =IFERROR(__xludf.DUMMYFUNCTION("""COMPUTED_VALUE"""),"DE JONG") -> DE JONG | C31: =IFERROR(__xludf.DUMMYFUNCTION("""COMPUTED_VALUE"""),"FC BARCELONA") -> FC BARCELONA | D31: =IFERROR(__xludf.DUMMYFUNCTION("""COMPUTED_VALUE"""),1.0) -> 1
A32: =IFERROR(__xludf.DUMMYFUNCTION("""COMPUTED_VALUE"""),65.0) -> 65 | B32: =IFERROR(__xludf.DUMMYFUNCTION("""COMPUTED_VALUE"""),"PEDRI") -> PEDRI | C32: =IFERROR(__xludf.DUMMYFUNCTION("""COMPUTED_VALUE"""),"FC BARCELONA") -> FC BARCELONA | D32: =IFERROR(__xludf.DUMMYFUNCTION("""COMPUTED_VALUE"""),1.0) -> 1
A33: =IFERROR(__xludf.DUMMYFUNCTION("""COMPUTED_VALUE"""),66.0) -> 66 | B33: =IFERROR(__xludf.DUMMYFUNCTION("""COMPUTED_VALUE"""),"FERMÍN") -> FERMÍN | C33: =IFERROR(__xludf.DUMMYFUNCTION("""COMPUTED_VALUE"""),"FC BARCELONA") -> FC BARCELONA | D33: =IFERROR(__xludf.DUMMYFUNCTION("""COMPUTED_VALUE"""),1.0) -> 1
A34: =IFERROR(__xludf.DUMMYFUNCTION("""COMPUTED_VALUE"""),67.0) -> 67 | B34: =IFERROR(__xludf.DUMMYFUNCTION("""COMPUTED_VALUE"""),"DANI OLMO") -> DANI OLMO | C34: =IFERROR(__xludf.DUMMYFUNCTION("""COMPUTED_VALUE"""),"FC BARCELONA") -> FC BARCELONA | D34: =IFERROR(__xludf.DUMMYFUNCTION("""COMPUTED_VALUE"""),2.0) -> 2
A35: =IFERROR(__xludf.DUMMYFUNCTION("""COMPUTED_VALUE"""),72.0) -> 72 | B35: =IFERROR(__xludf.DUMMYFUNCTION("""COMPUTED_VALUE"""),"RASHFORD") -> RASHFORD | C35: =IFERROR(__xludf.DUMMYFUNCTION("""COMPUTED_VALUE"""),"FC BARCELONA") -> FC BARCELONA | D35: =IFERROR(__xludf.DUMMYFUNCTION("""COMPUTED_VALUE"""),1.0) -> 1
A36: =IFERROR(__xludf.DUMMYFUNCTION("""COMPUTED_VALUE"""),73.0) -> 73 | B36: =IFERROR(__xludf.DUMMYFUNCTION("""COMPUTED_VALUE"""),"ESCUDO") -> ESCUDO | C36: =IFERROR(__xludf.DUMMYFUNCTION("""COMPUTED_VALUE"""),"REAL BETIS") -> REAL BETIS | D36: =IFERROR(__xludf.DUMMYFUNCTION("""COMPUTED_VALUE"""),1.0) -> 1
A37: =IFERROR(__xludf.DUMMYFUNCTION("""COMPUTED_VALUE"""),74.0) -> 74 | B37: =IFERROR(__xludf.DUMMYFUNCTION("""COMPUTED_VALUE"""),"PAU LÓPEZ") -> PAU LÓPEZ | C37: =IFERROR(__xludf.DUMMYFUNCTION("""COMPUTED_VALUE"""),"REAL BETIS") -> REAL BETIS | D37: =IFERROR(__xludf.DUMMYFUNCTION("""COMPUTED_VALUE"""),2.0) -> 2
A38: =IFERROR(__xludf.DUMMYFUNCTION("""COMPUTED_VALUE"""),75.0) -> 75 | B38: =IFERROR(__xludf.DUMMYFUNCTION("""COMPUTED_VALUE"""),"VALLES") -> VALLES | C38: =IFERROR(__xludf.DUMMYFUNCTION("""COMPUTED_VALUE"""),"REAL BETIS") -> REAL BETIS | D38: =IFERROR(__xludf.DUMMYFUNCTION("""COMPUTED_VALUE"""),1.0) -> 1
A39: =IFERROR(__xludf.DUMMYFUNCTION("""COMPUTED_VALUE"""),76.0) -> 76 | B39: =IFERROR(__xludf.DUMMYFUNCTION("""COMPUTED_VALUE"""),"BELLERÍN") -> BELLERÍN | C39: =IFERROR(__xludf.DUMMYFUNCTION("""COMPUTED_VALUE"""),"REAL BETIS") -> REAL BETIS | D39: =IFERROR(__xludf.DUMMYFUNCTION("""COMPUTED_VALUE"""),1.0) -> 1
A40: =IFERROR(__xludf.DUMMYFUNCTION("""COMPUTED_VALUE"""),79.0) -> 79 | B40: =IFERROR(__xludf.DUMMYFUNCTION("""COMPUTED_VALUE"""),"NATAN") -> NATAN | C40: =IFERROR(__xludf.DUMMYFUNCTION("""COMPUTED_VALUE"""),"REAL BETIS") -> REAL BETIS | D40: =IFERROR(__xludf.DUMMYFUNCTION("""COMPUTED_VALUE"""),1.0) -> 1
...

Sheet REGULARES
A1: 1 | B1: ESCUDO | C1: D. ALAVÉS | D1: SI | E1: 1
A2: 2 | B2: SIVERA | C2: D. ALAVÉS | D2: SI
A3: 3 | B3: RAÚL FERNÁNDEZ | C3: D. ALAVÉS | D3: SI | E3: 1
A4: 4 | B4: JONNY | C4: D. ALAVÉS | D4: SI | E4: 1
A5: 5 | B5: TENAGLIA | C5: D. ALAVÉS | D5: SI | E5: 1
A6: 6 | B6: PACHECO | C6: D. ALAVÉS | D6: SI
A7: 7 | B7: PARADA | C7: D. ALAVÉS | D7: SI | E7: 1
A8: 8 | B8: MOUSSA DIARRA | C8: D. ALAVÉS | D8: SI | E8: 1
A9: 9 | B9: BLANCO | C9: D. ALAVÉS | D9: SI
A10: 10 | B10: GUEVARA | C10: D. ALAVÉS | D10: SI
A11: 11 | B11: GURIDI | C11: D. ALAVÉS | D11: SI
A12: 12 | B12: ALEÑÁ | C12: D. ALAVÉS | D12: SI
A13: 13 | B13: PABLO IBÁÑEZ | C13: D. ALAVÉS
A14: 14 | B14: DENIS SUÁREZ | C14: D. ALAVÉS | D14: SI
A15: 15 | B15: CARLOS VICENTE | C15: D. ALAVÉS | D15: SI | E15: 1
A16: 16 | B16: TONI MARTÍNEZ | C16: D. ALAVÉS | D16: SI | E16: 1
A17: 17 | B17: BOYÉ | C17: D. ALAVÉS | D17: SI | E17: 1
A18: 18 | B18: MARIANO | C18: D. ALAVÉS | D18: SI | E18: 2
A19: 19 | B19: ESCUDO | C19: ATHLETIC CLUB | D19: SI | E19: 1
A20: 20 | B20: UNAI SIMÓN | C20: ATHLETIC CLUB
A21: 21 | B21: PADILLA | C21: ATHLETIC CLUB | D21: SI | E21: 1
A22: 22 | B22: ARESO | C22: ATHLETIC CLUB | D22: SI
A23: 23 | B23: VIVIAN | C23: ATHLETIC CLUB | D23: SI | E23: 2
A24: 24 | B24: PAREDES | C24: ATHLETIC CLUB | D24: SI
A25: 25 | B25: LAPORTE | C25: ATHLETIC CLUB | D25: SI
A26: 26 | B26: YURI | C26: ATHLETIC CLUB
A27: 27 | B27: RUIZ DE GALARRETA | C27: ATHLETIC CLUB | D27: SI | E27: 1
A28: 28 | B28: JAUREGIZAR | C28: ATHLETIC CLUB | D28: SI
A29: 29 | B29: VESGA | C29: ATHLETIC CLUB | D29: SI
A30: 30 | B30: UNAI GÓMEZ | C30: ATHLETIC CLUB | D30: SI
A31: 31 | B31: SANCET | C31: ATHLETIC CLUB | D31: SI | E31: 1
A32: 32 | B32: BERENGUER | C32: ATHLETIC CLUB | D32: SI | E32: 1
A33: 33 | B33: WILLIAMS | C33: ATHLETIC CLUB | D33: SI | E33: 1
A34: 34 | B34: MAROAN | C34: ATHLETIC CLUB | D34: SI | E34: 1
A35: 35 | B35: GURUZETA | C35: ATHLETIC CLUB | D35: SI
A36: 36 | B36: NICO WILLIAMS | C36: ATHLETIC CLUB | D36: SI
A37: 37 | B37: ESCUDO | C37: ATLÉTICO DE MADRID | D37: SI
A38: 38 | B38: OBLAK | C38: ATLÉTICO DE MADRID | D38: SI
A39: 39 | B39: MUSSO | C39: ATLÉTICO DE MADRID | D39: SI | E39: 2
A40: 40 | B40: MARCOS LLORENTE | C40: ATLÉTICO DE MADRID | D40: SI | E40: 1
...

Sheet Estadios
A1: 1 | B1: ESTADIO | C1: D. ALAVÉS | D1: SI | E1: 2
A2: 19 | B2: ESTADIO | C2: ATHLETIC CLUB | D2: SI | E2: 2
A3: 37 | B3: ESTADIO | C3: ATLÉTICO DE MADRID | D3: SI | E3: 1
A4: 55 | B4: ESTADIO | C4: FC BARCELONA | D4: SI | E4: 1
A5: 73 | B5: ESTADIO | C5: REAL BETIS | D5: SI | E5: 1
A6: 91 | B6: ESTADIO | C6: RC CELTA | D6: SI
A7: 109 | B7: ESTADIO | C7: ELCHE CF | D7: SI | E7: 1
A8: 127 | B8: ESTADIO | C8: RCD ESPANYOL | D8: SI | E8: 1
A9: 145 | B9: ESTADIO | C9: GETAFE CF | D9: SI | E9: 1
A10: 163 | B10: ESTADIO | C10: GIRONA FC | D10: SI
A11: 181 | B11: ESTADIO | C11: LEVANTE UD | D11: SI
A12: 199 | B12: ESTADIO | C12: REAL MADRID | D12: SI | E12: 2
A13: 217 | B13: ESTADIO | C13: RCD MALLORCA | D13: SI | E13: 1
A14: 235 | B14: ESTADIO | C14: CA OSASUNA | D14: SI | E14: 3
A15: 253 | B15: ESTADIO | C15: REAL OVIEDO | D15: SI | E15: 1
A16: 271 | B16: ESTADIO | C16: RAYO VALLECANO | D16: SI | E16: 2
A17: 289 | B17: ESTADIO | C17: REAL SOCIEDAD | D17: SI
A18: 307 | B18: ESTADIO | C18: SEVILLA FC | D18: SI | E18: 2
A19: 325 | B19: ESTADIO | C19: VALENCIA CF | D19: SI | E19: 2
A20: 343 | B20: ESTADIO | C20: VILLARREAL CF | D20: SI | E20: 2

Sheet ¡VAMOS! (361–380)
A1: 361 | B1: D. ALAVÉS | C1: ¡VAMOS! | D1: SI | E1: 3
A2: 362 | B2: ATHLETIC CLUB | C2: ¡VAMOS! | D2: SI
A3: 363 | B3: ATLÉTICO DE MADRID | C3: ¡VAMOS! | D3: SI | E3: 1
A4: 364 | B4: FC BARCELONA | C4: ¡VAMOS! | D4: SI
A5: 365 | B5: REAL BETIS | C5: ¡VAMOS! | D5: SI
A6: 366 | B6: RC CELTA | C6: ¡VAMOS! | D6: SI | E6: 1
A7: 367 | B7: ELCHE CF | C7: ¡VAMOS! | D7: SI
A8: 368 | B8: RCD ESPANYOL | C8: ¡VAMOS! | D8: SI
A9: 369 | B9: GETAFE CF | C9: ¡VAMOS! | D9: SI | E9: 1
A10: 370 | B10: GIRONA FC | C10: ¡VAMOS! | D10: SI
A11: 371 | B11: LEVANTE UD | C11: ¡VAMOS! | D11: SI | E11: 2
A12: 372 | B12: REAL MADRID | C12: ¡VAMOS! | D12: SI | E12: 1
A13: 373 | B13: RCD MALLORCA | C13: ¡VAMOS! | D13: SI
A14: 374 | B14: CA OSASUNA | C14: ¡VAMOS! | D14: SI
A15: 375 | B15: REAL OVIEDO | C15: ¡VAMOS! | D15: SI
A16: 376 | B16: RAYO VALLECANO | C16: ¡VAMOS! | D16: SI | E16: 1
A17: 377 | B17: REAL SOCIEDAD | C17: ¡VAMOS! | D17: SI | E17: 1
A18: 378 | B18: SEVILLA FC | C18: ¡VAMOS! | D18: SI | E18: 1
A19: 379 | B19: VALENCIA CF | C19: ¡VAMOS! | D19: SI
A20: 380 | B20: VILLARREAL CF | C20: ¡VAMOS!

Sheet Guantes de Oro (381–387)
A1: 381 | B1: SIVERA | C1: D. ALAVÉS | D1: SI
A2: 382 | B2: JOAN GARCÍA | C2: FC BARCELONA | D2: SI
A3: 383 | B3: DAVID SORIA | C3: GETAFE CF | D3: SI | E3: 1
A4: 384 | B4: SERGIO HERRERA | C4: CA OSASUNA | D4: SI
A5: 385 | B5: BATALLA | C5: RAYO VALLECANO
A6: 386 | B6: REMIRO | C6: REAL SOCIEDAD | D6: SI | E6: 1
A7: 387 | B7: AGIRREZABALA | C7: VALENCIA CF | D7: SI | E7: 3
A8: 499 | B8: DMITROVIC | C8: RCD ESPANYOL
A9: 500 | B9: TER STEGEN | C9: GIRONA FC

Sheet Kryptonita (388–396)
A1: 388 | B1: LAPORTE | C1: ATHLETIC CLUB | D1: SI
A2: 389 | B2: VIVIAN | C2: ATHLETIC CLUB | D2: SI
A3: 390 | B3: LE NORMAND | C3: ATLÉTICO DE MADRID
A4: 391 | B4: AFFENGRUBER | C4: ELCHE CF | D4: SI | E4: 1
A5: 392 | B5: CABRERA | C5: RCD ESPANYOL | D5: SI | E5: 1
A6: 393 | B6: MILITAO | C6: REAL MADRID | D6: SI | E6: 1
A7: 394 | B7: LEJEUNE | C7: RAYO VALLECANO
A8: 395 | B8: TÁRREGA | C8: VALENCIA CF | D8: SI
A9: 396 | B9: MOURIÑO | C9: VILLARREAL CF | D9: SI | E9: 1
A10: 501 | B10: PUBILL | C10: ATLÉTICO DE MADRID
A11: 502 | B11: GERARD MARTÍN | C11: FC BARCELONA
A12: 503 | B12: ASENCIO | C12: REAL MADRID

Sheet Diamantes (397–414)
A1: 397 | B1: REGO | C1: ATHLETIC CLUB | D1: SI | E1: 1
A2: 398 | B2: DRO | C2: FC BARCELONA | D2: SI | E2: 1
A3: 399 | B3: VALENTÍN GÓMEZ | C3: REAL BETIS | D3: SI | E3: 1
A4: 400 | B4: PABLO GARCÍA | C4: REAL BETIS | D4: SI
A5: 401 | B5: RODRI MENDOZA | C5: ELCHE CF | D5: SI | E5: 2
A6: 402 | B6: RIEDEL | C6: RCD ESPANYOL | D6: SI | E6: 1
A7: 403 | B7: DAVINCHI | C7: GETAFE CF | D7: SI | E7: 1
A8: 404 | B8: LISO | C8: GETAFE CF | D8: SI | E8: 2
A9: 405 | B9: VITOR REIS | C9: GIRONA FC | D9: SI | E9: 1
A10: 406 | B10: JOEL ROCA | C10: GIRONA FC | D10: SI
A11: 407 | B11: CARLOS ÁLVAREZ | C11: LEVANTE UD | D11: SI | E11: 2
A12: 408 | B12: ETTA EYONG | C12: LEVANTE UD | D12: SI | E12: 2
A13: 409 | B13: FRAN GONZÁLEZ | C13: REAL MADRID | D13: SI | E13: 1
A14: 410 | B14: GONZALO | C14: REAL MADRID | D14: SI
A15: 411 | B15: JAN VIRGILI | C15: RCD MALLORCA | D15: SI
A16: 412 | B16: MATEO JOSEPH | C16: RCD MALLORCA
A17: 413 | B17: VÍCTOR MUÑOZ | C17: CA OSASUNA | D17: SI | E17: 1
A18: 414 | B18: RENATO VEIGA | C18: VILLARREAL CF | D18: SI | E18: 1

Sheet Influencers (415–423)
A1: 415 | B1: BARRIOS | C1: ATLÉTICO DE MADRID | D1: SI | E1: 1
A2: 415 Bis | B2: RUIZ DE GALARRETA | C2: ATHLETIC CLUB | D2: SI
A3: 416 | B3: SOTELO | C3: RC CELTA | D3: SI | E3: 1
A4: 416 Bis | B4: PABLO FORNALS | C4: REAL BETIS
A5: 417 | B5: FEBAS | C5: ELCHE CF | D5: SI
A6: 417 Bis | B6: PABLO TORRE | C6: RCD MALLORCA | D6: SI | E6: 1
A7: 418 | B7: EDU EXPÓSITO | C7: RCD ESPANYOL | D7: SI | E7: 1
A8: 418 Bis | B8: PAPE GUEYE | C8: VILLARREAL CF | D8: SI
A9: 419 | B9: MILLA | C9: GETAFE CF | D9: SI | E9: 1
A10: 420 | B10: DARDER | C10: RCD MALLORCA | D10: SI
A11: 421 | B11: AIMAR OROZ | C11: CA OSASUNA | D11: SI | E11: 1
A12: 422 | B12: CAZORLA | C12: REAL OVIEDO | D12: SI | E12: 2
A13: 423 | B13: UNAI LÓPEZ | C13: RAYO VALLECANO | D13: SI

Sheet Protas (424–441)
A1: 424 | B1: TENAGLIA | C1: D. ALAVÉS | D1: SI | E1: 1
A2: 425 | B2: CARLOS VICENTE | C2: D. ALAVÉS | D2: SI | E2: 1
A3: 426 | B3: ERIC GARCÍA | C3: FC BARCELONA | D3: SI
A4: 427 | B4: CUCHO HERNÁNDEZ | C4: REAL BETIS | D4: SI
A5: 428 | B5: BORJA IGLESIAS | C5: RC CELTA | D5: SI
A6: 429 | B6: DOLAN | C6: RCD ESPANYOL | D6: SI
A7: 430 | B7: VANAT | C7: GIRONA FC | D7: SI
A8: 431 | B8: MANU SÁNCHEZ | C8: LEVANTE UD | D8: SI | E8: 1
A9: 432 | B9: TCHOUAMÉNI | C9: REAL MADRID | D9: SI
A10: 433 | B10: LEO ROMÁN | C10: RCD MALLORCA | D10: SI
A11: 434 | B11: AARON ESCANDELL | C11: REAL OVIEDO | D11: SI | E11: 1
A12: 435 | B12: HASSAN | C12: REAL OVIEDO | D12: SI
A13: 436 | B13: CARLOS SOLER | C13: REAL SOCIEDAD | D13: SI | E13: 1
A14: 437 | B14: GORROTXATEGI | C14: REAL SOCIEDAD | D14: SI | E14: 1
A15: 438 | B15: BATISTA MENDY | C15: SEVILLA FC | D15: SI
A16: 439 | B16: ALEXIS SÁNCHEZ | C16: SEVILLA FC | D16: SI | E16: 1
A17: 440 | B17: DANJUMA | C17: VALENCIA CF | D17: SI
A18: 441 | B18: BUCHANAN | C18: VILLARREAL CF | D18: SI | E18: 1

Sheet Cartas Top y Únicas (468–478)
A1: 468 | B1: CARD CHAMPIONS | C1: ÚNICA | D1: SI
A2: 469 | B2: NICO WILLIAMS | C2: BALÓN DE ORO (ATHLETIC) | D2: SI | E2: 1
A3: 470 | B3: JULIÁN ÁLVAREZ | C3: BALÓN DE ORO (ATLÉTICO)
A4: 471 | B4: PEDRI | C4: BALÓN DE ORO (BARÇA)
A5: 472 | B5: LAMINE YAMAL | C5: BALÓN DE ORO (BARÇA)
A6: 473 | B6: VINÍCIUS | C6: BALÓN DE ORO (REAL MADRID) | D6: SI | E6: 1
A7: 474 | B7: MBAPPÉ | C7: BALÓN DE ORO (REAL MADRID) | D7: SI
A8: 475 | B8: BALÓN DE ORO EXCELLENCE | C8: ÚNICA | D8: SI
A9: 476 | B9: CARD ATÓMICA | C9: ÚNICA
A10: 477 | B10: CARD INVENCIBLE | C10: ÚNICA | D10: SI
A11: 478 | B11: CAMPEÓN CARD | C11: ÚNICA | D11: SI
A12: 1MN | B12: VLACHODIMOS | C12: SEVILLA FC | D12: SI
A13: 2MN | B13: RADU | C13: CELTA
A14: 3MN | B14: TRENT | C14: REAL MADRID | D14: SI | E14: 1
A15: 4MN | B15: CALETA-CAR | C15: REAL SOCIEDAD | D15: SI | E15: 2
A16: 5MN | B16: HACNKO | C16: ATLETICO DE MADRID | D16: SI
A17: 6MN | B17: SUAZO | C17: SEVILLA FC
A18: 7MN | B18: NICO GONZALEZ | C18: ATLETICO DE MADRID | D18: SI
A19: 8MN | B19: SANTAMARIA | C19: VALENCIA CF | D19: SI | E19: 1
A20: 9MN | B20: AMRABAT | C20: REAL BETIS | D20: SI | E20: 1
A21: 10MN | B21: MASTANTUONDO | C21: REAL MADRID | D21: SI
A22: 11MN | B22: ALMADA | C22: ATLETICO DE MADRID | D22: SI | E22: 1
A23: 12MN | B23: DOLAN | C23: RCD ESPANYOL
A24: 13MN | B24: MIKAUTADZE | C24: VILLAREAL CF
A25: 14MN | B25: RASHFORD | C25: FC BARCELONA | D25: SI | E25: 1
A26: 15MN | B26: OLUWASEVI | C26: VILLAREAL CF | D26: SI

Sheet Super Cracks (442–467)
A1: 442 | B1: UNAI SIMÓN | C1: ATHLETIC CLUB | D1: SI
A2: 443 | B2: JAUREGIZAR | C2: ATHLETIC CLUB
A3: 444 | B3: OBLAK | C3: ATLÉTICO DE MADRID | D3: SI
A4: 445 | B4: MARCOS LLORENTE | C4: ATLÉTICO DE MADRID | D4: SI | E4: 2
A5: 446 | B5: ÁLEX BAENA | C5: ATLÉTICO DE MADRID | D5: SI
A6: 447 | B6: ALMADA | C6: ATLÉTICO DE MADRID | D6: SI | E6: 1
A7: 448 | B7: GRIEZMANN | C7: ATLÉTICO DE MADRID | D7: SI | E7: 1
A8: 449 | B8: KOUNDÉ | C8: FC BARCELONA | D8: SI
A9: 450 | B9: BALDE | C9: FC BARCELONA | D9: SI
A10: 451 | B10: RAPHINHA | C10: FC BARCELONA | D10: SI | E10: 1
A11: 452 | B11: LEWANDOWSKI | C11: FC BARCELONA | D11: SI | E11: 1
A12: 453 | B12: RASHFORD | C12: FC BARCELONA
A13: 454 | B13: ISCO | C13: REAL BETIS | D13: SI
A14: 455 | B14: LO CELSO | C14: REAL BETIS | D14: SI | E14: 2
A15: 456 | B15: ANTONY | C15: REAL BETIS | D15: SI
A16: 457 | B16: COURTOIS | C16: REAL MADRID | D16: SI | E16: 1
A17: 458 | B17: CARRERAS | C17: REAL MADRID | D17: SI | E17: 2
A18: 459 | B18: FEDE VALVERDE | C18: REAL MADRID | D18: SI
A19: 460 | B19: MASTANTUONO | C19: REAL MADRID | D19: SI | E19: 1
A20: 461 | B20: BUDIMIR | C20: CA OSASUNA | D20: SI
A21: 462 | B21: ISI | C21: RAYO VALLECANO | D21: SI | E21: 1
A22: 463 | B22: KUBO | C22: REAL SOCIEDAD | D22: SI
A23: 464 | B23: VARGAS | C23: SEVILLA FC | D23: SI
A24: 465 | B24: JAVI GUERRA | C24: VALENCIA CF | D24: SI | E24: 1
A25: 466 | B25: MOLEIRO | C25: VILLARREAL CF | D25: SI
A26: 467 | B26: PÉPÉ | C26: VILLARREAL CF | D26: SI

Sheet AMPLIACION
A1: 7 BIS | B1: BORJA GARCÉS | C1: D. Alavés | D1: SI
A2: 8 BIS | B2: YUSI ENRÍQUEZ | C2: D. Alavés | D2: SI | E2: 1
A3: 15 BIS | B3: ÁNGEL PÉREZ | C3: D. Alavés | D3: SI
A4: 16 BIS | B4: CALEBE GONÇALVES | C4: D. Alavés
A5: 18 BIS | B5: ABDE REBBACH | C5: D. Alavés | D5: SI
A6: 22 BIS | B6: ANDONI GOROSABEL | C6: Athletic Club
A7: 29 BIS | B7: SELTON BIAI | C7: Athletic Club | D7: SI | E7: 1
A8: 30 BIS | B8: MIKEL REGO | C8: Athletic Club | D8: SI
A9: 32 BIS | B9: ROBERT NAVARRO | C9: Athletic Club | D9: SI
A10: 40 BIS | B10: NAHUEL MOLINA | C10: Atlético de Madrid | D10: SI | E10: 1
A11: 41 BIS | B11: MARC PUBILL | C11: Atlético de Madrid
A12: 42 BIS | B12: JOSÉ MARÍA GIMÉNEZ | C12: Atlético de Madrid | D12: SI
A13: 44 BIS | B13: JAVI GALÁN | C13: Atlético de Madrid | D13: SI
A14: 46 BIS | B14: OBED VARGAS | C14: Atlético de Madrid
A15: 47 BIS | B15: JOHNNY CARDOSO | C15: Atlético de Madrid
A16: 48 BIS | B16: RODRI MENDOZA | C16: Atlético de Madrid
A17: 51 BIS | B17: GIACOMO RASPADORI | C17: Atlético de Madrid | D17: SI
A18: 54 BIS | B18: ADEMOLA LOOKMAN | C18: Atlético de Madrid
A19: 58 BIS | B19: JOAO CANCELO | C19: FC Barcelona | D19: SI
A20: 60 BIS | B20: GERARD MARTÍN | C20: FC Barcelona
A21: 63 BIS | B21: MARC BERNAL | C21: FC Barcelona | D21: SI | E21: 1
A22: 64 BIS | B22: MARC CASADÓ | C22: FC Barcelona | D22: SI
A23: 70 BIS | B23: ROONY BARDGHJI | C23: FC Barcelona | D23: SI
A24: 76 BIS | B24: AITOR RUIBAL | C24: Real Betis
A25: 82 BIS | B25: NELSON DEOSSA | C25: Real Betis
A26: 84 BIS | B26: ÁLVARO FIDALGO | C26: Real Betis
A27: 85 BIS | B27: MARC ROCA | C27: Real Betis | D27: SI
A28: 89 BIS | B28: PABLO GARCÍA | C28: Real Betis | D28: SI
A29: 90 BIS | B29: CHIMY ÁVILA | C29: Real Betis | D29: SI | E29: 1
A30: 94 BIS | B30: ÁLVARO NÚÑEZ | C30: RC Celta | D30: SI
A31: 96 BIS | B31: YOEL LAGO | C31: RC Celta | D31: SI
A32: 101 BIS | B32: MIGUEL ROMÁN | C32: RC Celta
A33: 102 BIS | B33: THIAGO VECINO | C33: RC Celta
A34: 104 BIS | B34: FER LÓPEZ | C34: RC Celta | D34: SI
A35: 105 BIS | B35: ANOUAR EL-ABDELLAOUI | C35: RC Celta | D35: SI | E35: 1
A36: 108 BIS | B36: PABLO DURÁN | C36: RC Celta | D36: SI
A37: 112 BIS | B37: HÉCTOR FORT | C37: Elche CF | D37: SI
A38: 117 BIS | B38: GONZALO VILLAR | C38: Elche CF
A39: 122 BIS | B39: TETE MORENTE | C39: Elche CF
A40: 123 BIS | B40: JAVI CEPEDA | C40: Elche CF
...

Sheet ESPECIALES
A1: 1 Momentum | B1: Koke | C1: Atlético de Madrid | D1: SI | E1: 1
A2: 2 Momentum | B2: Pedri | C2: FC Barcelona
A3: 3 Momentum | B3: Iago Aspas | C3: RC Celta
A4: 4 Momentum | B4: Etta Eyong | C4: UD Levante
A5: 5 Momentum | B5: Álvaro García | C5: Rayo Vallecano
A6: 1 Maxi Momentum | B6: Lamine Yamal / Vinicius | C6: Varios
A7: 1 Míticos Invencible | B7: Puro Oro | C7: Varios
A8: 2 Míticos Invencible | B8: Atleti Atleti! | C8: Atlético de Madrid
A9: 1 Panini Extra Gold | B9: Lamine Yamal | C9: FC Barcelona
A10: 2 Panini Extra Gold | B10: Mbappé | C10: Real Madrid
A11: 1 Edición Limitada (Megapack) | B11: Nico González | C11: Atlético de Madrid | D11: SI
A12: 2 Edición Limitada (Megapack) | B12: De Jong | C12: FC Barcelona | D12: SI
A13: 3 Edición Limitada (Megapack) | B13: Huijsen | C13: Real Madrid | D13: SI
A14: 1 Edición Limitada (Tin Box) | B14: Sancet | C14: Athletic Club
A15: 2 Edición Limitada (Tin Box) | B15: Koke | C15: Atlético de Madrid
A16: 3 Edición Limitada (Tin Box) | B16: Güler | C16: Real Madrid
A17: 4 Edición Limitada (Tin Box) | B17: Mikautadze | C17: Villarreal CF
A18: 1 Edición Limitada (Pocket Box) | B18: Cazorla (Platinum 2026) | C18: Real Oviedo | D18: SI
A19: 2 Edición Limitada (Pocket Box) | B19: Fermín | C19: FC Barcelona | D19: SI
A20: 3 Edición Limitada (Pocket Box) | B20: Iago Aspas | C20: RC Celta | D20: SI
A21: 4 Edición Limitada (Pocket Box) | B21: Muriqi | C21: RCD Mallorca | D21: SI
A22: 1 Sobre Premium | B22: Williams | C22: Athletic Club | D22: SI
A23: 2 Sobre Premium | B23: Williams (Firma Serigrafiada) | C23: Athletic Club | D23: SI
A24: 3 Sobre Premium | B24: Ferran Torres | C24: FC Barcelona | D24: SI
A25: 4 Sobre Premium | B25: Ferran Torres (Firma Serigrafiada) | C25: FC Barcelona
A26: 5 Sobre Premium | B26: Oyarzabal | C26: Real Sociedad | D26: SI
A27: 6 Sobre Premium | B27: Oyarzabal (Firma Serigrafiada) | C27: Real Sociedad | D27: SI
A28: 7 Sobre Premium | B28: Ayoze | C28: Villarreal CF
A29: 8 Sobre Premium | B29: Ayoze (Firma Serigrafiada) | C29: Villarreal CF
A30: 1 Sobre Premium Oro | B30: Pedri (Premium Oro) | C30: FC Barcelona | D30: SI
A31: 2 Sobre Premium Oro | B31: Lamine Yamal (Premium Oro) | C31: FC Barcelona | D31: SI
A32: 3 Sobre Premium Oro | B32: Isco (Premium Oro) | C32: Real Betis | D32: SI
A33: 4 Sobre Premium Oro | B33: Joan García (Revelación Oro) | C33: FC Barcelona | D33: SI
A34: 5 Sobre Premium Oro | B34: Hancko | C34: Atlético de Madrid | D34: SI
A35: 6 Sobre Premium Oro | B35: Bellingham | C35: Real Madrid | D35: SI
A36: 7 Sobre Premium Oro | B36: De Frutos | C36: Rayo Vallecano | D36: SI
A37: 8 Sobre Premium Oro | B37: Lookman | C37: Atlético de Madrid | D37: SI
A38: Mom Oro Billion | B38: Nico Williams / Williams | C38: Athletic Club | D38: SI
A39: Mom Oro Billion | B39: Ferran Torres / Lamine Yamal | C39: FC Barcelona | D39: SI
A40: Mom Oro Billion | B40: Vinícius / Mbappé | C40: Real Madrid | D40: SI
...
